<?xml version="1.0" ?>
<robot name="moodz" xmlns:xacro="http://www.ros.org/wiki/xacro">
<xacro:include filename="$(find moodz_description)/urdf/materials.xacro" />
<xacro:include filename="$(find moodz_description)/urdf/moodz.trans" />
<xacro:include filename="$(find moodz_description)/urdf/moodz.gazebo" />

<link name="panda_link0">
    <visual>
        <geometry>
            <mesh filename="package://franka_description/meshes/visual/link0.dae" />
        </geometry>
    </visual>
    <collision>
        <origin rpy="0 1.5707963267948966 0" xyz="-0.075 0 0.06" />
        <geometry>
            <cylinder length="0.03" radius="0.09" />
        </geometry>
    </collision>
    <collision>
        <origin rpy="0 0 0" xyz="-0.06 0 0.06" />
        <geometry>
            <sphere radius="0.09" />
        </geometry>
    </collision>
    <collision>
        <origin rpy="0 0 0" xyz="-0.09 0 0.06" />
        <geometry>
            <sphere radius="0.09" />
        </geometry>
    </collision>
    <inertial>
        <mass value="0.1" />
        <origin xyz="0 0 0" rpy="0 0 0" />
        <inertia ixx="0.03" iyy="0.03" izz="0.03" ixy="0.0" ixz="0.0" iyz="0.0" />
    </inertial>
</link>
<link name="panda_link1">
    <visual>
        <geometry>
            <mesh filename="package://franka_description/meshes/visual/link1.dae" />
        </geometry>
    </visual>
    <collision>
        <origin rpy="0 0 0" xyz="0 0 -0.1915" />
        <geometry>
            <cylinder length="0.2830" radius="0.09" />
        </geometry>
    </collision>
    <collision>
        <origin rpy="0 0 0" xyz="0 0 -0.333" />
        <geometry>
            <sphere radius="0.09" />
        </geometry>
    </collision>
    <collision>
        <origin rpy="0 0 0" xyz="0 0 -0.05" />
        <geometry>
            <sphere radius="0.09" />
        </geometry>
    </collision>
    <inertial>
        <mass value="0.1" />
        <origin xyz="0 0 0" rpy="0 0 0" />
        <inertia ixx="0.03" iyy="0.03" izz="0.03" ixy="0.0" ixz="0.0" iyz="0.0" />
    </inertial>
</link>

<link name="panda_link2">
    <visual>
        <geometry>
            <mesh filename="package://franka_description/meshes/visual/link2.dae" />
        </geometry>
    </visual>
    <collision>
        <origin rpy="0 0 0" xyz="0 0 0" />
        <geometry>
            <cylinder length="0.012" radius="0.09" />
        </geometry>
    </collision>
    <collision>
        <origin rpy="0 0 0" xyz="0 0 -0.06" />
        <geometry>
            <sphere radius="0.09" />
        </geometry>
    </collision>
    <collision>
        <origin rpy="0 0 0" xyz="0 0 0.06" />
        <geometry>
            <sphere radius="0.09" />
        </geometry>
    </collision>
    <inertial>
        <mass value="0.1" />
        <origin xyz="0 0 0" rpy="0 0 0" />
        <inertia ixx="0.03" iyy="0.03" izz="0.03" ixy="0.0" ixz="0.0" iyz="0.0" />
    </inertial>
</link>

<link name="panda_link3">
    <visual>
        <geometry>
            <mesh filename="package://franka_description/meshes/visual/link3.dae" />
        </geometry>
    </visual>
    <collision>
        <origin rpy="0 0 0" xyz="0 0 -0.145" />
        <geometry>
            <cylinder length="0.15" radius="0.09" />
        </geometry>
    </collision>
    <collision>
        <origin rpy="0 0 0" xyz="0 0 -0.22" />
        <geometry>
            <sphere radius="0.09" />
        </geometry>
    </collision>
    <collision>
        <origin rpy="0 0 0" xyz="0 0 -0.07" />
        <geometry>
            <sphere radius="0.09" />
        </geometry>
    </collision>
    <inertial>
        <mass value="0.1" />
        <origin xyz="0 0 0" rpy="0 0 0" />
        <inertia ixx="0.03" iyy="0.03" izz="0.03" ixy="0.0" ixz="0.0" iyz="0.0" />
    </inertial>
</link>

<link name="panda_link4">
    <visual>
        <geometry>
            <mesh filename="package://franka_description/meshes/visual/link4.dae" />
        </geometry>
    </visual>
    <collision>
        <origin rpy="0 0 0" xyz="0 0 0" />
        <geometry>
            <cylinder length="0.12" radius="0.09" />
        </geometry>
    </collision>
    <collision>
        <origin rpy="0 0 0" xyz="0 0 0.06" />
        <geometry>
            <sphere radius="0.09" />
        </geometry>
    </collision>
    <collision>
        <origin rpy="0 0 0" xyz="0 0 -0.06" />
        <geometry>
            <sphere radius="0.09" />
        </geometry>
    </collision>
    <inertial>
        <mass value="0.1" />
        <origin xyz="0 0 0" rpy="0 0 0" />
        <inertia ixx="0.03" iyy="0.03" izz="0.03" ixy="0.0" ixz="0.0" iyz="0.0" />
    </inertial>
</link>

<link name="panda_link5">
    <visual>
        <geometry>
            <mesh filename="package://franka_description/meshes/visual/link5.dae" />
        </geometry>
    </visual>
    <collision>
        <origin rpy="0 0 0" xyz="0 0 -0.26" />
        <geometry>
            <cylinder length="0.1" radius="0.09" />
        </geometry>
    </collision>
    <collision>
        <origin rpy="0 0 0" xyz="0 0 -0.31" />
        <geometry>
            <sphere radius="0.09" />
        </geometry>
    </collision>
    <collision>
        <origin rpy="0 0 0" xyz="0 0 -0.21" />
        <geometry>
            <sphere radius="0.09" />
        </geometry>
    </collision>
    <collision>
        <origin rpy="0 0 0" xyz="0 0.08 -0.13" />
        <geometry>
            <cylinder length="0.14" radius="0.055" />
        </geometry>
    </collision>
    <collision>
        <origin rpy="0 0 0" xyz="0 0.08 -0.06" />
        <geometry>
            <sphere radius="0.055" />
        </geometry>
    </collision>
    <collision>
        <origin rpy="0 0 0" xyz="0 0.08 -0.20" />
        <geometry>
            <sphere radius="0.055" />
        </geometry>
    </collision>
    <inertial>
        <mass value="0.1" />
        <origin xyz="0 0 0" rpy="0 0 0" />
        <inertia ixx="0.03" iyy="0.03" izz="0.03" ixy="0.0" ixz="0.0" iyz="0.0" />
    </inertial>
</link>

<link name="panda_link6">
    <visual>
        <geometry>
            <mesh filename="package://franka_description/meshes/visual/link6.dae" />
        </geometry>
    </visual>
    <collision>
        <origin rpy="0 0 0" xyz="0 0 -0.03" />
        <geometry>
            <cylinder length="0.08" radius="0.08" />
        </geometry>
    </collision>
    <collision>
        <origin rpy="0 0 0" xyz="0 0 0.01" />
        <geometry>
            <sphere radius="0.08" />
        </geometry>
    </collision>
    <collision>
        <origin rpy="0 0 0" xyz="0 0 -0.07" />
        <geometry>
            <sphere radius="0.08" />
        </geometry>
    </collision>
    <inertial>
        <mass value="0.1" />
        <origin xyz="0 0 0" rpy="0 0 0" />
        <inertia ixx="0.03" iyy="0.03" izz="0.03" ixy="0.0" ixz="0.0" iyz="0.0" />
    </inertial>
</link>

<link name="panda_link7">
    <visual>
        <geometry>
            <mesh filename="package://franka_description/meshes/visual/link7.dae" />
        </geometry>
    </visual>
    <collision>
        <origin rpy="0 0 0" xyz="0 0 0.01" />
        <geometry>
            <cylinder length="0.14" radius="0.07" />
        </geometry>
    </collision>
    <collision>
        <origin rpy="0 0 0" xyz="0 0 0.08" />
        <geometry>
            <sphere radius="0.07" />
        </geometry>
    </collision>
    <collision>
        <origin rpy="0 0 0" xyz="0 0 -0.06" />
        <geometry>
            <sphere radius="0.07" />
        </geometry>
    </collision>
    <inertial>
        <mass value="0.1" />
        <origin xyz="0 0 0" rpy="0 0 0" />
        <inertia ixx="0.03" iyy="0.03" izz="0.03" ixy="0.0" ixz="0.0" iyz="0.0" />
    </inertial>
</link>

<link name="panda_link8">
    <collision>
        <origin rpy="3.141592653589793 1.5707963267948966 1.5707963267948966" xyz="0.0424 0.0424 -0.0250" />
        <geometry>
            <cylinder length="0.01" radius="0.06" />
        </geometry>
    </collision>
    <collision>
        <origin rpy="0 0 0" xyz="0.0424 0.0424 -0.02" />
        <geometry>
            <sphere radius="0.06" />
        </geometry>
    </collision>
    <collision>
        <origin rpy="0 0 0" xyz="0.0424 0.0424 -0.03" />
        <geometry>
            <sphere radius="0.06" />
        </geometry>
    </collision>
    <inertial>
        <mass value="0.1" />
        <origin xyz="0 0 0" rpy="0 0 0" />
        <inertia ixx="0.03" iyy="0.03" izz="0.03" ixy="0.0" ixz="0.0" iyz="0.0" />
    </inertial>
</link>
<link name="base_link">
  <inertial>
    <origin rpy="0 0 0" xyz="0.003563875604623609 3.688815650635801e-17 0.14918957693465243"/>
    <mass value="33.45253675533549"/>
    <inertia ixx="0.504373" ixy="0.0" ixz="-0.01326" iyy="0.793057" iyz="0.0" izz="1.138721"/>
  </inertial>
  <visual>
    <origin rpy="0 0 0" xyz="0 0 0"/>
    <geometry>
      <mesh filename="package://moodz_description/meshes/base_link.stl" scale="0.001 0.001 0.001"/>
    </geometry>
    <material name="silver"/>
  </visual>
  <collision>
    <origin rpy="0 0 0" xyz="0 0 0"/>
    <geometry>
      <mesh filename="package://moodz_description/meshes/base_link.stl" scale="0.001 0.001 0.001"/>
    </geometry>
  </collision>
</link>

<link name="right_wheel_1">
  <inertial>
    <origin rpy="0 0 0" xyz="0.0 -0.03750000000000003 2.7755575615628914e-17"/>
    <mass value="4.93033697072748"/>
    <inertia ixx="0.030044" ixy="0.0" ixz="-0.0" iyy="0.055466" iyz="-0.0" izz="0.030044"/>
  </inertial>
  <visual>
    <origin rpy="0 0 0" xyz="-0.0 0.2 -0.15"/>
    <geometry>
      <mesh filename="package://moodz_description/meshes/right_wheel_1.stl" scale="0.001 0.001 0.001"/>
    </geometry>
    <material name="silver"/>
  </visual>
  <collision>
    <origin rpy="0 0 0" xyz="-0.0 0.2 -0.15"/>
    <geometry>
      <mesh filename="package://moodz_description/meshes/right_wheel_1.stl" scale="0.001 0.001 0.001"/>
    </geometry>
  </collision>
</link>

<link name="left_wheel_1">
  <inertial>
    <origin rpy="0 0 0" xyz="0.0 0.03749999999999998 2.7755575615628914e-17"/>
    <mass value="4.93033697072748"/>
    <inertia ixx="0.030044" ixy="0.0" ixz="-0.0" iyy="0.055466" iyz="0.0" izz="0.030044"/>
  </inertial>
  <visual>
    <origin rpy="0 0 0" xyz="-0.0 -0.2 -0.15"/>
    <geometry>
      <mesh filename="package://moodz_description/meshes/left_wheel_1.stl" scale="0.001 0.001 0.001"/>
    </geometry>
    <material name="silver"/>
  </visual>
  <collision>
    <origin rpy="0 0 0" xyz="-0.0 -0.2 -0.15"/>
    <geometry>
      <mesh filename="package://moodz_description/meshes/left_wheel_1.stl" scale="0.001 0.001 0.001"/>
    </geometry>
  </collision>
</link>

<link name="lidar_1">
  <inertial>
    <origin rpy="0 0 0" xyz="-2.7755575615628914e-17 5.790023100122029e-18 0.024999999999999967"/>
    <mass value="0.5615596868291755"/>
    <inertia ixx="0.000468" ixy="0.0" ixz="-0.0" iyy="0.000468" iyz="0.0" izz="0.000702"/>
  </inertial>
  <visual>
    <origin rpy="0 0 0" xyz="-0.175 -0.0 -0.3"/>
    <geometry>
      <mesh filename="package://moodz_description/meshes/lidar_1.stl" scale="0.001 0.001 0.001"/>
    </geometry>
    <material name="silver"/>
  </visual>
  <collision>
    <origin rpy="0 0 0" xyz="-0.175 -0.0 -0.3"/>
    <geometry>
      <mesh filename="package://moodz_description/meshes/lidar_1.stl" scale="0.001 0.001 0.001"/>
    </geometry>
  </collision>
</link>

<link name="camera_1">
  <inertial>
    <origin rpy="0 0 0" xyz="0.012500000000000011 0.0 0.0"/>
    <mass value="0.3575"/>
    <inertia ixx="0.001266" ixy="0.0" ixz="0.0" iyy="9.3e-05" iyz="0.0" izz="0.00121"/>
  </inertial>
  <visual>
    <origin rpy="0 0 0" xyz="-0.25 -0.0 -0.15"/>
    <geometry>
      <mesh filename="package://moodz_description/meshes/camera_1.stl" scale="0.001 0.001 0.001"/>
    </geometry>
    <material name="silver"/>
  </visual>
  <collision>
    <origin rpy="0 0 0" xyz="-0.25 -0.0 -0.15"/>
    <geometry>
      <mesh filename="package://moodz_description/meshes/camera_1.stl" scale="0.001 0.001 0.001"/>
    </geometry>
  </collision>
</link>
<link name="camera_link_optical">
</link>
<joint name="camera_optical_joint" type="fixed">
    <origin xyz="0 0 0" rpy="-1.58 0 -1.58"/>
    <parent link="camera_1"/>
    <child link="camera_link_optical"/>
</joint>

<joint name="base_arm_connector" type="fixed">
  <origin rpy="0 0 0" xyz="0.05 0.0 0.25"/>
  <parent link="base_link"/>
  <child link="panda_link0"/>
  <axis xyz="0.0 0.0 1.0"/>
</joint>

<joint name="Rev1" type="continuous">
  <origin rpy="0 0 0" xyz="0.0 -0.2 0.15"/>
  <parent link="base_link"/>
  <child link="right_wheel_1"/>
  <axis xyz="0.0 1.0 0.0"/>
</joint>

<joint name="Rev2" type="continuous">
  <origin rpy="0 0 0" xyz="0.0 0.2 0.15"/>
  <parent link="base_link"/>
  <child link="left_wheel_1"/>
  <axis xyz="0.0 1.0 0.0"/>
</joint>

<joint name="Rev3" type="fixed">
  <origin rpy="0 0 0" xyz="0.175 0.0 0.3"/>
  <parent link="base_link"/>
  <child link="lidar_1"/>
  <axis xyz="0.0 1.0 0.0"/>
</joint>

<joint name="Rigid4" type="fixed">
  <origin rpy="0 0 0" xyz="0.25 0.0 0.15"/>
  <parent link="base_link"/>
  <child link="camera_1"/>
  <axis xyz="0 1 0"/>
</joint>

<joint name="panda_joint8" type="fixed">
    <origin rpy="0 0 0" xyz="0 0 0.107" />
    <parent link="panda_link7" />
    <child link="panda_link8" />
</joint>

<joint name="panda_joint1" type="revolute">
    <safety_controller k_position="100.0" k_velocity="40.0" soft_lower_limit="-2.8973" soft_upper_limit="2.8973" />
    <origin rpy="0 0 0" xyz="0 0 0.333" />
    <parent link="panda_link0" />
    <child link="panda_link1" />
    <axis xyz="0 0 1" />
    <limit effort="87" lower="-2.8973" upper="2.8973" velocity="2.1750" />
</joint>

<joint name="panda_joint2" type="revolute">
    <safety_controller k_position="100.0" k_velocity="40.0" soft_lower_limit="-1.7628" soft_upper_limit="1.7628" />
    <origin rpy="-1.5707963267948966 0 0" xyz="0 0 0" />
    <parent link="panda_link1" />
    <child link="panda_link2" />
    <axis xyz="0 0 1" />
    <limit effort="87" lower="-1.7628" upper="1.7628" velocity="2.1750" />
</joint>

<joint name="panda_joint3" type="revolute">
    <safety_controller k_position="100.0" k_velocity="40.0" soft_lower_limit="-2.8973" soft_upper_limit="2.8973" />
    <origin rpy="1.5707963267948966 0 0" xyz="0 -0.316 0" />
    <parent link="panda_link2" />
    <child link="panda_link3" />
    <axis xyz="0 0 1" />
    <limit effort="87" lower="-2.8973" upper="2.8973" velocity="2.1750" />
</joint>

<joint name="panda_joint4" type="revolute">
    <safety_controller k_position="100.0" k_velocity="40.0" soft_lower_limit="-3.0718" soft_upper_limit="-0.0698" />
    <origin rpy="1.5707963267948966 0 0" xyz="0.0825 0 0" />
    <parent link="panda_link3" />
    <child link="panda_link4" />
    <axis xyz="0 0 1" />
    <limit effort="87" lower="-3.0718" upper="-0.0698" velocity="2.1750" />
</joint>

<joint name="panda_joint5" type="revolute">
    <safety_controller k_position="100.0" k_velocity="40.0" soft_lower_limit="-2.8973" soft_upper_limit="2.8973" />
    <origin rpy="-1.5707963267948966 0 0" xyz="-0.0825 0.384 0" />
    <parent link="panda_link4" />
    <child link="panda_link5" />
    <axis xyz="0 0 1" />
    <limit effort="12" lower="-2.8973" upper="2.8973" velocity="2.6100" />
</joint>

<joint name="panda_joint6" type="revolute">
    <safety_controller k_position="100.0" k_velocity="40.0" soft_lower_limit="-0.0175" soft_upper_limit="3.7525" />
    <origin rpy="1.5707963267948966 0 0" xyz="0 0 0" />
    <parent link="panda_link5" />
    <child link="panda_link6" />
    <axis xyz="0 0 1" />
    <limit effort="12" lower="-0.0175" upper="3.7525" velocity="2.6100" />
</joint>

<joint name="panda_joint7" type="revolute">
    <safety_controller k_position="100.0" k_velocity="40.0" soft_lower_limit="-2.8973" soft_upper_limit="2.8973" />
    <origin rpy="1.5707963267948966 0 0" xyz="0.088 0 0" />
    <parent link="panda_link6" />
    <child link="panda_link7" />
    <axis xyz="0 0 1" />
    <limit effort="12" lower="-2.8973" upper="2.8973" velocity="2.6100" />
</joint>

</robot>

